Workbook

Sheet Market Size
A1: Total Companies | B1: 500000 | C1: 5000 | D1: =B1/C1 -> 100
A2: Recruite per company (Annual) | B2: 5
A3: Total Recruitement | B3: =B1*B2 -> 2500000
A4: Online Ad Posting Conversion | B4: 0.1
A5: Total online ad posting (Annual) | B5: =B3*B4 -> 250000
A6: X Market Share | B6: 0.5
A7: X Total potantioal Ad posting (Annual) | B7: =B5*B6 -> 125000
A8: X Total potantioal Ad posting (Monthly) | B8: =B7/12 -> 10416.667
A9: Average Ad Cost (IRT) - First Year | B9: =Assumptions!B7 -> 250000
A10: Average Ad Cost (IRT) - Last Year | B10: =B9*(1+Assumptions!B2)^5 -> 762939.45
A11: SOM (IRT) - Last Month of the Last Year | B11: =B10*B7 -> 9.5367432e+10

Sheet Assumptions
A1: Economy Assumption
A2: Inflation | B2: 0.25 | E2: TAX | F2: 0.25
A3: Wage Growth | B3: 0.2 | E3: Depreciation | F3: 0.2
A5: Revenue Assumptions
A6: Years | B6: Year 1 | C6: Year 2 | D6: Year 3 | E6: Year 4 | F6: Year 5
A7: Average Ad Cost (IRT) | B7: 250000 | C7: =B7*(1+B2) -> 312500 | D7: =B7*(1+B2)^2 -> 390625 | E7: =B7*(1+B2)^3 -> 488281.25 | F7: =B7*(1+B2)^4 -> 610351.56
A9: Marketing Assumptions
A10: Disscount and Promotions / Sales | B10: 0.1
A11: Years | B11: Year 1 | C11: Year 2 | D11: Year 3 | E11: Year 4 | F11: Year 5
A12: Cost per Ad | B12: 20000 | C12: =B12*(1+C13) -> 29000 | D12: =C12*(1+D13) -> 39150 | E12: =D12*(1+E13) -> 48937.5 | F12: =E12*(1+F13) -> 70959.375
A13: Acquisition Cost (New Users) | C13: 0.45 | D13: 0.35 | E13: 0.25 | F13: 0.45
A14: ATL/ Revenue | B14: 0.1
A16: Payroll Assumption
A17: Years | B17: Salary | C17: Year 1 | D17: Year 2 | E17: Year 3 | F17: Year 4 | G17: Year 5
A18: C-Level | B18: 20000000 | C18: 3 | D18: 5 | E18: 6 | F18: 7 | G18: 7
A19: Tech | B19: 18000000 | C19: 2 | D19: 6 | E19: 8 | F19: 12 | G19: 15
A20: Expert | B20: 14000000 | C20: 4 | D20: =D19*2 -> 12 | E20: =E19*2 -> 16 | F20: =F19*2 -> 24 | G20: 30
A21: Support | B21: 6000000 | C21: 5 | D21: =C21*(1+$H$21) -> 5 | E21: =D21*(1+$H$21) -> 5 | F21: =E21*(1+$H$21) -> 5 | G21: 30
A22: Overhead | B22: 0.38
B23: Total Personnel | C23: =SUM(C18,C19,C20,C21) -> 14 | D23: =SUM(D18,D19,D20,D21) -> 28 | E23: =SUM(E18,E19,E20,E21) -> 35 | F23: =SUM(F18,F19,F20,F21) -> 48 | G23: =SUM(G18,G19,G20,G21) -> 82
A25: Other Assumptions
A26: Rent Per person | B26: 700000
A27: Utilities per person | B27: 200000
A28: Asset Per person Per month | B28: =10000000/12 -> 833333.33
A30: other cost/total Cost | B30: 0.05

Sheet Growth Model
B1: Year 0 | C1: Year 1 | D1: Year 2 | E1: Year 3 | F1: Year 4 | G1: Year 5
A2: Acqusitions | B2: =B4/G4 -> 0.0096 | C2: =2.5%-B2 -> 0.0154 | D2: 0.135 | E2: 0.34 | F2: 0.34 | G2: 0.16
A3: Rogers Model | B3: =B2 -> 0.0096 | C3: =C2+B3 -> 0.025 | D3: =D2+C3 -> 0.16 | E3: =E2+D3 -> 0.5 | F3: =F2+E3 -> 0.84 | G3: =G2+F3 -> 1
A4: Last Month Ads | B4: 100 | C4: =C3*$G$4 -> 260.41667 | D4: =D3*$G$4 -> 1666.6667 | E4: =E3*$G$4 -> 5208.3333 | F4: =F3*$G$4 -> 8750 | G4: ='Market Size'!B8 -> 10416.667
A5: CAGR | B5: =((G4/B4)^(1/5))-1 -> 1.5324784 | C5: =(C4/B4)-1 -> 1.6041667 | D5: =(D4/C4)-1 -> 5.4 | E5: =(E4/D4)-1 -> 2.125 | F5: =(F4/E4)-1 -> 0.68 | G5: =(G4/F4)-1 -> 0.19047619
A6: CMGR | C6: =((C4/B4)^(1/12))-1 -> 0.083026454 | D6: =((D4/C4)^(1/12))-1 -> 0.16729779 | E6: =((E4/D4)^(1/12))-1 -> 0.099607015 | F6: =((F4/E4)^(1/12))-1 -> 0.044180969 | G6: =((G4/F4)^(1/12))-1 -> 0.014635514
A7: Revenue Growth | B7: =B4*Assumptions!B7 -> 25000000 | C7: =C4*Assumptions!$B$7 -> 65104167 | D7: =D4*Assumptions!$B$7*(1+Assumptions!$B$2) -> 5.2083333e+08 | E7: =E4*Assumptions!$B$7*(1+Assumptions!$B$2)^2 -> 2.0345052e+09 | F7: =F4*Assumptions!$B$7*(1+Assumptions!$B$2)^3 -> 4.2724609e+09 | G7: =G4*Assumptions!$B$7*(1+Assumptions!$B$2)^4 -> 6.3578288e+09

Sheet KPI Growth
A1: Years | B1: Year 0 | C1: Year 1 | O1: Year 2 | AA1: Year 3 | AM1: Year 4 | AY1: Year 5
A2: Months | B2: 0 | C2: 1 | D2: 2 | E2: 3 | F2: 4 | G2: 5 | H2: 6 | I2: 7 | J2: 8 | K2: 9 | L2: 10 | M2: 11 | N2: 12 | O2: 13 | P2: 14 | Q2: 15 | R2: 16 | S2: 17 | T2: 18 | U2: 19 | V2: 20 | W2: 21 | X2: 22 | Y2: 23 | Z2: 24 | AA2: 25 | AB2: 26 | AC2: 27 | AD2: 28 | AE2: 29 | AF2: 30 | AG2: 31 | AH2: 32 | AI2: 33 | AJ2: 34 | AK2: 35 | AL2: 36 | AM2: 37 | AN2: 38 | AO2: 39 | AP2: 40 | AQ2: 41 | AR2: 42 | AS2: 43 | AT2: 44 | AU2: 45 | AV2: 46 | AW2: 47 | AX2: 48 | AY2: 49 | AZ2: 50 | BA2: 51 | BB2: 52 | BC2: 53 | BD2: 54 | BE2: 55 | BF2: 56 | BG2: 57 | BH2: 58 | BI2: 59 | BJ2: 60
A3: KPI Growth | B3: ='[1]Growth Model'!B4 -> 100 | C3: =B3+$C$4*B3 -> 108.30265 | D3: =C3+$C$4*C3 -> 117.29463 | E3: =D3+$C$4*D3 -> 127.03319 | F3: =E3+$C$4*E3 -> 137.5803 | G3: =F3+$C$4*F3 -> 149.00311 | H3: =G3+$C$4*G3 -> 161.37431 | I3: =H3+$C$4*H3 -> 174.77264 | J3: =I3+$C$4*I3 -> 189.2834 | ... M3: =L3+$C$4*L3 -> 240.45273 | N3: ='[1]Growth Model'!C4 -> 260.41667 | O3: =N3+N3*$O$4 -> 303.9838 | P3: =O3+O3*$O$4 -> 354.83962 | Q3: =P3+P3*$O$4 -> 414.2035 | R3: =Q3+Q3*$O$4 -> 483.49884 | S3: =R3+R3*$O$4 -> 564.38713 | T3: =S3+S3*$O$4 -> 658.80785 | U3: =T3+T3*$O$4 -> 769.02494 | V3: =U3+U3*$O$4 -> 897.68112 | ... Y3: =X3+X3*$O$4 -> 1427.799 | Z3: ='[1]Growth Model'!D4 -> 1666.6667 | AA3: =Z3+Z3*$AA$4 -> 1832.6784 | AB3: =AA3+AA3*$AA$4 -> 2015.226 | AC3: =AB3+AB3*$AA$4 -> 2215.9566 | AD3: =AC3+AC3*$AA$4 -> 2436.6814 | AE3: =AD3+AD3*$AA$4 -> 2679.392 | AF3: =AE3+AE3*$AA$4 -> 2946.2783 | AG3: =AF3+AF3*$AA$4 -> 3239.7482 | AH3: =AG3+AG3*$AA$4 -> 3562.4499 | ... AK3: =AJ3+AJ3*$AA$4 -> 4736.5407 | AL3: ='[1]Growth Model'!E4 -> 5208.3333 | AM3: =AL3+AL3*$AM$4 -> 5438.4425 | AN3: =AM3+AM3*$AM$4 -> 5678.7182 | AO3: =AN3+AN3*$AM$4 -> 5929.6095 | AP3: =AO3+AO3*$AM$4 -> 6191.5854 | AQ3: =AP3+AP3*$AM$4 -> 6465.1356 | AR3: =AQ3+AQ3*$AM$4 -> 6750.7716 | AS3: =AR3+AR3*$AM$4 -> 7049.0272 | AT3: =AS3+AS3*$AM$4 -> 7360.46 | ... AW3: =AV3+AV3*$AM$4 -> 8379.7735 | AX3: ='[1]Growth Model'!F4 -> 8750 | AY3: =AX3+AX3*$AY$4 -> 8878.0608 | AZ3: =AY3+AY3*$AY$4 -> 9007.9957 | BA3: =AZ3+AZ3*$AY$4 -> 9139.8324 | BB3: =BA3+BA3*$AY$4 -> 9273.5985 | BC3: =BB3+BB3*$AY$4 -> 9409.3224 | BD3: =BC3+BC3*$AY$4 -> 9547.0327 | BE3: =BD3+BD3*$AY$4 -> 9686.7584 | BF3: =BE3+BE3*$AY$4 -> 9828.5291 | ... BI3: =BH3+BH3*$AY$4 -> 10266.412 | BJ3: ='[1]Growth Model'!G4 -> 10416.667
A4: CMGR | C4: =(N3/B3)^(1/12)-1 -> 0.083026454 | O4: =(Z3/N3)^(1/12)-1 -> 0.16729779 | AA4: =(AL3/Z3)^(1/12)-1 -> 0.099607015 | AM4: =(AX3/AL3)^(1/12)-1 -> 0.044180969 | AY4: =(BJ3/AX3)^(1/12)-1 -> 0.014635514
A5: Annual Ads | C5: =SUM(C3:N3) -> 2092.5318 | O5: =SUM(O3:Z3) -> 9811.9198 | AA5: =SUM(AA3:AL3) -> 39098.065 | AM5: =SUM(AM3:AX3) -> 83704.388 | AY5: =SUM(AY3:BJ3) -> 115544.91
A6: Monthly Revenue (IRMT) | B6: =B3*Assumptions!B7/1000000 -> 25 | C6: =C3*Assumptions!$B$7/1000000 -> 27.075661 | D6: =D3*Assumptions!$B$7/1000000 -> 29.323657 | E6: =E3*Assumptions!$B$7/1000000 -> 31.758297 | F6: =F3*Assumptions!$B$7/1000000 -> 34.395076 | G6: =G3*Assumptions!$B$7/1000000 -> 37.250777 | H6: =H3*Assumptions!$B$7/1000000 -> 40.343577 | I6: =I3*Assumptions!$B$7/1000000 -> 43.693161 | J6: =J3*Assumptions!$B$7/1000000 -> 47.320849 | ... N6: =N3*Assumptions!$B$7/1000000 -> 65.104167 | O6: =O3*Assumptions!$C$7/1000000 -> 94.994938 | P6: =P3*Assumptions!$C$7/1000000 -> 110.88738 | Q6: =Q3*Assumptions!$C$7/1000000 -> 129.4386 | R6: =R3*Assumptions!$C$7/1000000 -> 151.09339 | S6: =S3*Assumptions!$C$7/1000000 -> 176.37098 | T6: =T3*Assumptions!$C$7/1000000 -> 205.87745 | U6: =U3*Assumptions!$C$7/1000000 -> 240.3203 | V6: =V3*Assumptions!$C$7/1000000 -> 280.52535 | ... Z6: =Z3*Assumptions!$C$7/1000000 -> 520.83333 | AA6: =AA3*Assumptions!$D$7/1000000 -> 715.88998 | AB6: =AB3*Assumptions!$D$7/1000000 -> 787.19765 | AC6: =AC3*Assumptions!$D$7/1000000 -> 865.60806 | AD6: =AD3*Assumptions!$D$7/1000000 -> 951.82869 | AE6: =AE3*Assumptions!$D$7/1000000 -> 1046.6375 | AF6: =AF3*Assumptions!$D$7/1000000 -> 1150.8899 | AG6: =AG3*Assumptions!$D$7/1000000 -> 1265.5267 | AH6: =AH3*Assumptions!$D$7/1000000 -> 1391.582 | ... AL6: =AL3*Assumptions!$D$7/1000000 -> 2034.5052 | AM6: =AM3*Assumptions!$E$7/1000000 -> 2655.4895 | AN6: =AN3*Assumptions!$E$7/1000000 -> 2772.8116 | AO6: =AO3*Assumptions!$E$7/1000000 -> 2895.3171 | AP6: =AP3*Assumptions!$E$7/1000000 -> 3023.235 | AQ6: =AQ3*Assumptions!$E$7/1000000 -> 3156.8045 | AR6: =AR3*Assumptions!$E$7/1000000 -> 3296.2752 | AS6: =AS3*Assumptions!$E$7/1000000 -> 3441.9078 | AT6: =AT3*Assumptions!$E$7/1000000 -> 3593.9746 | ... AX6: =AX3*Assumptions!$E$7/1000000 -> 4272.4609 | AY6: =AY3*Assumptions!$F$7/1000000 -> 5418.7383 | AZ6: =AZ3*Assumptions!$F$7/1000000 -> 5498.0443 | BA6: =BA3*Assumptions!$F$7/1000000 -> 5578.511 | BB6: =BB3*Assumptions!$F$7/1000000 -> 5660.1554 | BC6: =BC3*Assumptions!$F$7/1000000 -> 5742.9946 | BD6: =BD3*Assumptions!$F$7/1000000 -> 5827.0463 | BE6: =BE3*Assumptions!$F$7/1000000 -> 5912.3281 | BF6: =BF3*Assumptions!$F$7/1000000 -> 5998.8581 | ... BJ6: =BJ3*Assumptions!$F$7/1000000 -> 6357.8288
A7: Revenue Monthly Growth Rate | C7: =(C6-B6)/B6 -> 0.083026454 | D7: =(D6-C6)/C6 -> 0.083026454 | E7: =(E6-D6)/D6 -> 0.083026454 | F7: =(F6-E6)/E6 -> 0.083026454 | G7: =(G6-F6)/F6 -> 0.083026454 | H7: =(H6-G6)/G6 -> 0.083026454 | I7: =(I6-H6)/H6 -> 0.083026454 | J7: =(J6-I6)/I6 -> 0.083026454 | ... BJ7: =(BJ6-BI6)/BI6 -> 0.014635514

Sheet P&L
A1: Year | B1: Year 1 | N1: Year 2 | Z1: Year 3 | AL1: Year 4 | AX1: Year 5
A2: Month | B2: 1 | C2: 2 | D2: 3 | E2: 4 | F2: 5 | G2: 6 | H2: 7 | I2: 8 | J2: 9 | K2: 10 | L2: 11 | M2: 12 | N2: 13 | O2: 14 | P2: 15 | Q2: 16 | R2: 17 | S2: 18 | T2: 19 | U2: 20 | V2: 21 | W2: 22 | X2: 23 | Y2: 24 | Z2: 25 | AA2: 26 | AB2: 27 | AC2: 28 | AD2: 29 | AE2: 30 | AF2: 31 | AG2: 32 | AH2: 33 | AI2: 34 | AJ2: 35 | AK2: 36 | AL2: 37 | AM2: 38 | AN2: 39 | AO2: 40 | AP2: 41 | AQ2: 42 | AR2: 43 | AS2: 44 | AT2: 45 | AU2: 46 | AV2: 47 | AW2: 48 | AX2: 49 | AY2: 50 | AZ2: 51 | BA2: 52 | BB2: 53 | BC2: 54 | BD2: 55 | BE2: 56 | BF2: 57 | BG2: 58 | BH2: 59 | BI2: 60
A3: Ads | B3: ='KPI Growth'!C3 -> 108.30265 | C3: ='KPI Growth'!D3 -> 117.29463 | D3: ='KPI Growth'!E3 -> 127.03319 | E3: ='KPI Growth'!F3 -> 137.5803 | F3: ='KPI Growth'!G3 -> 149.00311 | G3: ='KPI Growth'!H3 -> 161.37431 | H3: ='KPI Growth'!I3 -> 174.77264 | I3: ='KPI Growth'!J3 -> 189.2834 | ... BI3: ='KPI Growth'!BJ3 -> 10416.667
A4: Total Sales | B4: =B3*Assumptions!$B$7 -> 27075661 | C4: =C3*Assumptions!$B$7 -> 29323657 | D4: =D3*Assumptions!$B$7 -> 31758297 | E4: =E3*Assumptions!$B$7 -> 34395076 | F4: =F3*Assumptions!$B$7 -> 37250777 | G4: =G3*Assumptions!$B$7 -> 40343577 | H4: =H3*Assumptions!$B$7 -> 43693161 | I4: =I3*Assumptions!$B$7 -> 47320849 | ... M4: =M3*Assumptions!$B$7 -> 65104167 | N4: =N3*Assumptions!$B$7*(1+Assumptions!$B$2) -> 94994938 | O4: =O3*Assumptions!$B$7*(1+Assumptions!$B$2) -> 1.1088738e+08 | P4: =P3*Assumptions!$B$7*(1+Assumptions!$B$2) -> 1.294386e+08 | Q4: =Q3*Assumptions!$B$7*(1+Assumptions!$B$2) -> 1.5109339e+08 | R4: =R3*Assumptions!$B$7*(1+Assumptions!$B$2) -> 1.7637098e+08 | S4: =S3*Assumptions!$B$7*(1+Assumptions!$B$2) -> 2.0587745e+08 | T4: =T3*Assumptions!$B$7*(1+Assumptions!$B$2) -> 2.403203e+08 | U4: =U3*Assumptions!$B$7*(1+Assumptions!$B$2) -> 2.8052535e+08 | ... Y4: =Y3*Assumptions!$B$7*(1+Assumptions!$B$2) -> 5.2083333e+08 | Z4: =Z3*Assumptions!$B$7*(1+Assumptions!$B$2)^2 -> 7.1588998e+08 | AA4: =AA3*Assumptions!$B$7*(1+Assumptions!$B$2)^2 -> 7.8719765e+08 | AB4: =AB3*Assumptions!$B$7*(1+Assumptions!$B$2)^2 -> 8.6560806e+08 | AC4: =AC3*Assumptions!$B$7*(1+Assumptions!$B$2)^2 -> 9.5182869e+08 | AD4: =AD3*Assumptions!$B$7*(1+Assumptions!$B$2)^2 -> 1.0466375e+09 | AE4: =AE3*Assumptions!$B$7*(1+Assumptions!$B$2)^2 -> 1.1508899e+09 | AF4: =AF3*Assumptions!$B$7*(1+Assumptions!$B$2)^2 -> 1.2655267e+09 | AG4: =AG3*Assumptions!$B$7*(1+Assumptions!$B$2)^2 -> 1.391582e+09 | ... AK4: =AK3*Assumptions!$B$7*(1+Assumptions!$B$2)^2 -> 2.0345052e+09 | AL4: =AL3*Assumptions!$B$7*(1+Assumptions!$B$2)^3 -> 2.6554895e+09 | AM4: =AM3*Assumptions!$B$7*(1+Assumptions!$B$2)^3 -> 2.7728116e+09 | AN4: =AN3*Assumptions!$B$7*(1+Assumptions!$B$2)^3 -> 2.8953171e+09 | AO4: =AO3*Assumptions!$B$7*(1+Assumptions!$B$2)^3 -> 3.023235e+09 | AP4: =AP3*Assumptions!$B$7*(1+Assumptions!$B$2)^3 -> 3.1568045e+09 | AQ4: =AQ3*Assumptions!$B$7*(1+Assumptions!$B$2)^3 -> 3.2962752e+09 | AR4: =AR3*Assumptions!$B$7*(1+Assumptions!$B$2)^3 -> 3.4419078e+09 | AS4: =AS3*Assumptions!$B$7*(1+Assumptions!$B$2)^3 -> 3.5939746e+09 | ... AW4: =AW3*Assumptions!$B$7*(1+Assumptions!$B$2)^3 -> 4.2724609e+09 | AX4: =AX3*Assumptions!$B$7*(1+Assumptions!$B$2)^4 -> 5.4187383e+09 | AY4: =AY3*Assumptions!$B$7*(1+Assumptions!$B$2)^4 -> 5.4980443e+09 | AZ4: =AZ3*Assumptions!$B$7*(1+Assumptions!$B$2)^4 -> 5.578511e+09 | BA4: =BA3*Assumptions!$B$7*(1+Assumptions!$B$2)^4 -> 5.6601554e+09 | BB4: =BB3*Assumptions!$B$7*(1+Assumptions!$B$2)^4 -> 5.7429946e+09 | BC4: =BC3*Assumptions!$B$7*(1+Assumptions!$B$2)^4 -> 5.8270463e+09 | BD4: =BD3*Assumptions!$B$7*(1+Assumptions!$B$2)^4 -> 5.9123281e+09 | BE4: =BE3*Assumptions!$B$7*(1+Assumptions!$B$2)^4 -> 5.9988581e+09 | ... BI4: =BI3*Assumptions!$B$7*(1+Assumptions!$B$2)^4 -> 6.3578288e+09
A5: COR | B5: =-Assumptions!$B$10*'P&L'!B4 -> -2707566.1 | C5: =-Assumptions!$B$10*'P&L'!C4 -> -2932365.7 | D5: =-Assumptions!$B$10*'P&L'!D4 -> -3175829.7 | E5: =-Assumptions!$B$10*'P&L'!E4 -> -3439507.6 | F5: =-Assumptions!$B$10*'P&L'!F4 -> -3725077.7 | G5: =-Assumptions!$B$10*'P&L'!G4 -> -4034357.7 | H5: =-Assumptions!$B$10*'P&L'!H4 -> -4369316.1 | I5: =-Assumptions!$B$10*'P&L'!I4 -> -4732084.9 | ... BI5: =-Assumptions!$B$10*'P&L'!BI4 -> -6.3578288e+08
A6: Revenue | B6: =B4+B5 -> 24368095 | C6: =C4+C5 -> 26391292 | D6: =D4+D5 -> 28582467 | E6: =E4+E5 -> 30955568 | F6: =F4+F5 -> 33525699 | G6: =G4+G5 -> 36309219 | H6: =H4+H5 -> 39323845 | I6: =I4+I5 -> 42588764 | ... BI6: =BI4+BI5 -> 5.7220459e+09
A8: Payroll
A9: C-Level | B9: =Assumptions!$B$18*Assumptions!$C$18 -> 60000000 | C9: =Assumptions!$B$18*Assumptions!$C$18 -> 60000000 | D9: =Assumptions!$B$18*Assumptions!$C$18 -> 60000000 | E9: =Assumptions!$B$18*Assumptions!$C$18 -> 60000000 | F9: =Assumptions!$B$18*Assumptions!$C$18 -> 60000000 | G9: =Assumptions!$B$18*Assumptions!$C$18 -> 60000000 | H9: =Assumptions!$B$18*Assumptions!$C$18 -> 60000000 | I9: =Assumptions!$B$18*Assumptions!$C$18 -> 60000000 | ... M9: =Assumptions!$B$18*Assumptions!$C$18 -> 60000000 | N9: =Assumptions!$B$18*Assumptions!$D$18*(1+Assumptions!$B$3) -> 120000000 | O9: =Assumptions!$B$18*Assumptions!$D$18*(1+Assumptions!$B$3) -> 120000000 | P9: =Assumptions!$B$18*Assumptions!$D$18*(1+Assumptions!$B$3) -> 120000000 | Q9: =Assumptions!$B$18*Assumptions!$D$18*(1+Assumptions!$B$3) -> 120000000 | R9: =Assumptions!$B$18*Assumptions!$D$18*(1+Assumptions!$B$3) -> 120000000 | S9: =Assumptions!$B$18*Assumptions!$D$18*(1+Assumptions!$B$3) -> 120000000 | T9: =Assumptions!$B$18*Assumptions!$D$18*(1+Assumptions!$B$3) -> 120000000 | U9: =Assumptions!$B$18*Assumptions!$D$18*(1+Assumptions!$B$3) -> 120000000 | ... Y9: =Assumptions!$B$18*Assumptions!$D$18*(1+Assumptions!$B$3) -> 120000000 | Z9: =Assumptions!$B$18*Assumptions!$E$18*(1+Assumptions!$B$3)^2 -> 172800000 | AA9: =Assumptions!$B$18*Assumptions!$E$18*(1+Assumptions!$B$3)^2 -> 172800000 | AB9: =Assumptions!$B$18*Assumptions!$E$18*(1+Assumptions!$B$3)^2 -> 172800000 | AC9: =Assumptions!$B$18*Assumptions!$E$18*(1+Assumptions!$B$3)^2 -> 172800000 | AD9: =Assumptions!$B$18*Assumptions!$E$18*(1+Assumptions!$B$3)^2 -> 172800000 | AE9: =Assumptions!$B$18*Assumptions!$E$18*(1+Assumptions!$B$3)^2 -> 172800000 | AF9: =Assumptions!$B$18*Assumptions!$E$18*(1+Assumptions!$B$3)^2 -> 172800000 | AG9: =Assumptions!$B$18*Assumptions!$E$18*(1+Assumptions!$B$3)^2 -> 172800000 | ... AK9: =Assumptions!$B$18*Assumptions!$E$18*(1+Assumptions!$B$3)^2 -> 172800000 | AL9: =Assumptions!$B$18*Assumptions!$F$18*(1+Assumptions!$B$3)^3 -> 241920000 | AM9: =Assumptions!$B$18*Assumptions!$F$18*(1+Assumptions!$B$3)^3 -> 241920000 | AN9: =Assumptions!$B$18*Assumptions!$F$18*(1+Assumptions!$B$3)^3 -> 241920000 | AO9: =Assumptions!$B$18*Assumptions!$F$18*(1+Assumptions!$B$3)^3 -> 241920000 | AP9: =Assumptions!$B$18*Assumptions!$F$18*(1+Assumptions!$B$3)^3 -> 241920000 | AQ9: =Assumptions!$B$18*Assumptions!$F$18*(1+Assumptions!$B$3)^3 -> 241920000 | AR9: =Assumptions!$B$18*Assumptions!$F$18*(1+Assumptions!$B$3)^3 -> 241920000 | AS9: =Assumptions!$B$18*Assumptions!$F$18*(1+Assumptions!$B$3)^3 -> 241920000 | ... AW9: =Assumptions!$B$18*Assumptions!$F$18*(1+Assumptions!$B$3)^3 -> 241920000 | AX9: =Assumptions!$B$18*Assumptions!$G$18*(1+Assumptions!$B$3)^4 -> 290304000 | AY9: =Assumptions!$B$18*Assumptions!$G$18*(1+Assumptions!$B$3)^4 -> 290304000 | AZ9: =Assumptions!$B$18*Assumptions!$G$18*(1+Assumptions!$B$3)^4 -> 290304000 | BA9: =Assumptions!$B$18*Assumptions!$G$18*(1+Assumptions!$B$3)^4 -> 290304000 | BB9: =Assumptions!$B$18*Assumptions!$G$18*(1+Assumptions!$B$3)^4 -> 290304000 | BC9: =Assumptions!$B$18*Assumptions!$G$18*(1+Assumptions!$B$3)^4 -> 290304000 | BD9: =Assumptions!$B$18*Assumptions!$G$18*(1+Assumptions!$B$3)^4 -> 290304000 | BE9: =Assumptions!$B$18*Assumptions!$G$18*(1+Assumptions!$B$3)^4 -> 290304000 | ... BI9: =Assumptions!$B$18*Assumptions!$G$18*(1+Assumptions!$B$3)^4 -> 290304000
A10: Tech | B10: =Assumptions!$B$19*Assumptions!$C$19 -> 36000000 | C10: =Assumptions!$B$19*Assumptions!$C$19 -> 36000000 | D10: =Assumptions!$B$19*Assumptions!$C$19 -> 36000000 | E10: =Assumptions!$B$19*Assumptions!$C$19 -> 36000000 | F10: =Assumptions!$B$19*Assumptions!$C$19 -> 36000000 | G10: =Assumptions!$B$19*Assumptions!$C$19 -> 36000000 | H10: =Assumptions!$B$19*Assumptions!$C$19 -> 36000000 | I10: =Assumptions!$B$19*Assumptions!$C$19 -> 36000000 | ... M10: =Assumptions!$B$19*Assumptions!$C$19 -> 36000000 | N10: =Assumptions!$B$19*Assumptions!$D$19*(1+Assumptions!$B$3) -> 129600000 | O10: =Assumptions!$B$19*Assumptions!$D$19*(1+Assumptions!$B$3) -> 129600000 | P10: =Assumptions!$B$19*Assumptions!$D$19*(1+Assumptions!$B$3) -> 129600000 | Q10: =Assumptions!$B$19*Assumptions!$D$19*(1+Assumptions!$B$3) -> 129600000 | R10: =Assumptions!$B$19*Assumptions!$D$19*(1+Assumptions!$B$3) -> 129600000 | S10: =Assumptions!$B$19*Assumptions!$D$19*(1+Assumptions!$B$3) -> 129600000 | T10: =Assumptions!$B$19*Assumptions!$D$19*(1+Assumptions!$B$3) -> 129600000 | U10: =Assumptions!$B$19*Assumptions!$D$19*(1+Assumptions!$B$3) -> 129600000 | ... Y10: =Assumptions!$B$19*Assumptions!$D$19*(1+Assumptions!$B$3) -> 129600000 | Z10: =Assumptions!$B$19*Assumptions!$D$19*(1+Assumptions!$B$3)^2 -> 155520000 | AA10: =Assumptions!$B$19*Assumptions!$D$19*(1+Assumptions!$B$3)^2 -> 155520000 | AB10: =Assumptions!$B$19*Assumptions!$D$19*(1+Assumptions!$B$3)^2 -> 155520000 | AC10: =Assumptions!$B$19*Assumptions!$D$19*(1+Assumptions!$B$3)^2 -> 155520000 | AD10: =Assumptions!$B$19*Assumptions!$D$19*(1+Assumptions!$B$3)^2 -> 155520000 | AE10: =Assumptions!$B$19*Assumptions!$D$19*(1+Assumptions!$B$3)^2 -> 155520000 | AF10: =Assumptions!$B$19*Assumptions!$D$19*(1+Assumptions!$B$3)^2 -> 155520000 | AG10: =Assumptions!$B$19*Assumptions!$D$19*(1+Assumptions!$B$3)^2 -> 155520000 | ... AK10: =Assumptions!$B$19*Assumptions!$D$19*(1+Assumptions!$B$3)^2 -> 155520000 | AL10: =Assumptions!$B$19*Assumptions!$D$19*(1+Assumptions!$B$3)^3 -> 186624000 | AM10: =Assumptions!$B$19*Assumptions!$D$19*(1+Assumptions!$B$3)^3 -> 186624000 | AN10: =Assumptions!$B$19*Assumptions!$D$19*(1+Assumptions!$B$3)^3 -> 186624000 | AO10: =Assumptions!$B$19*Assumptions!$D$19*(1+Assumptions!$B$3)^3 -> 186624000 | AP10: =Assumptions!$B$19*Assumptions!$D$19*(1+Assumptions!$B$3)^3 -> 186624000 | AQ10: =Assumptions!$B$19*Assumptions!$D$19*(1+Assumptions!$B$3)^3 -> 186624000 | AR10: =Assumptions!$B$19*Assumptions!$D$19*(1+Assumptions!$B$3)^3 -> 186624000 | AS10: =Assumptions!$B$19*Assumptions!$D$19*(1+Assumptions!$B$3)^3 -> 186624000 | ... AW10: =Assumptions!$B$19*Assumptions!$D$19*(1+Assumptions!$B$3)^3 -> 186624000 | AX10: =Assumptions!$B$19*Assumptions!$D$19*(1+Assumptions!$B$3)^4 -> 223948800 | AY10: =Assumptions!$B$19*Assumptions!$D$19*(1+Assumptions!$B$3)^4 -> 223948800 | AZ10: =Assumptions!$B$19*Assumptions!$D$19*(1+Assumptions!$B$3)^4 -> 223948800 | BA10: =Assumptions!$B$19*Assumptions!$D$19*(1+Assumptions!$B$3)^4 -> 223948800 | BB10: =Assumptions!$B$19*Assumptions!$D$19*(1+Assumptions!$B$3)^4 -> 223948800 | BC10: =Assumptions!$B$19*Assumptions!$D$19*(1+Assumptions!$B$3)^4 -> 223948800 | BD10: =Assumptions!$B$19*Assumptions!$D$19*(1+Assumptions!$B$3)^4 -> 223948800 | BE10: =Assumptions!$B$19*Assumptions!$D$19*(1+Assumptions!$B$3)^4 -> 223948800 | ... BI10: =Assumptions!$B$19*Assumptions!$D$19*(1+Assumptions!$B$3)^4 -> 223948800
A11: Expert | B11: =Assumptions!$B$20*Assumptions!$C$20 -> 56000000 | C11: =Assumptions!$B$20*Assumptions!$C$20 -> 56000000 | D11: =Assumptions!$B$20*Assumptions!$C$20 -> 56000000 | E11: =Assumptions!$B$20*Assumptions!$C$20 -> 56000000 | F11: =Assumptions!$B$20*Assumptions!$C$20 -> 56000000 | G11: =Assumptions!$B$20*Assumptions!$C$20 -> 56000000 | H11: =Assumptions!$B$20*Assumptions!$C$20 -> 56000000 | I11: =Assumptions!$B$20*Assumptions!$C$20 -> 56000000 | ... M11: =Assumptions!$B$20*Assumptions!$C$20 -> 56000000 | N11: =Assumptions!$B$20*Assumptions!$D$20*(1+Assumptions!$B$3) -> 201600000 | O11: =Assumptions!$B$20*Assumptions!$D$20*(1+Assumptions!$B$3) -> 201600000 | P11: =Assumptions!$B$20*Assumptions!$D$20*(1+Assumptions!$B$3) -> 201600000 | Q11: =Assumptions!$B$20*Assumptions!$D$20*(1+Assumptions!$B$3) -> 201600000 | R11: =Assumptions!$B$20*Assumptions!$D$20*(1+Assumptions!$B$3) -> 201600000 | S11: =Assumptions!$B$20*Assumptions!$D$20*(1+Assumptions!$B$3) -> 201600000 | T11: =Assumptions!$B$20*Assumptions!$D$20*(1+Assumptions!$B$3) -> 201600000 | U11: =Assumptions!$B$20*Assumptions!$D$20*(1+Assumptions!$B$3) -> 201600000 | ... Y11: =Assumptions!$B$20*Assumptions!$D$20*(1+Assumptions!$B$3) -> 201600000 | Z11: =Assumptions!$B$20*Assumptions!$D$20*(1+Assumptions!$B$3)^2 -> 241920000 | AA11: =Assumptions!$B$20*Assumptions!$D$20*(1+Assumptions!$B$3)^2 -> 241920000 | AB11: =Assumptions!$B$20*Assumptions!$D$20*(1+Assumptions!$B$3)^2 -> 241920000 | AC11: =Assumptions!$B$20*Assumptions!$D$20*(1+Assumptions!$B$3)^2 -> 241920000 | AD11: =Assumptions!$B$20*Assumptions!$D$20*(1+Assumptions!$B$3)^2 -> 241920000 | AE11: =Assumptions!$B$20*Assumptions!$D$20*(1+Assumptions!$B$3)^2 -> 241920000 | AF11: =Assumptions!$B$20*Assumptions!$D$20*(1+Assumptions!$B$3)^2 -> 241920000 | AG11: =Assumptions!$B$20*Assumptions!$D$20*(1+Assumptions!$B$3)^2 -> 241920000 | ... AK11: =Assumptions!$B$20*Assumptions!$D$20*(1+Assumptions!$B$3)^2 -> 241920000 | AL11: =Assumptions!$B$20*Assumptions!$D$20*(1+Assumptions!$B$3)^3 -> 290304000 | AM11: =Assumptions!$B$20*Assumptions!$D$20*(1+Assumptions!$B$3)^3 -> 290304000 | AN11: =Assumptions!$B$20*Assumptions!$D$20*(1+Assumptions!$B$3)^3 -> 290304000 | AO11: =Assumptions!$B$20*Assumptions!$D$20*(1+Assumptions!$B$3)^3 -> 290304000 | AP11: =Assumptions!$B$20*Assumptions!$D$20*(1+Assumptions!$B$3)^3 -> 290304000 | AQ11: =Assumptions!$B$20*Assumptions!$D$20*(1+Assumptions!$B$3)^3 -> 290304000 | AR11: =Assumptions!$B$20*Assumptions!$D$20*(1+Assumptions!$B$3)^3 -> 290304000 | AS11: =Assumptions!$B$20*Assumptions!$D$20*(1+Assumptions!$B$3)^3 -> 290304000 | ... AW11: =Assumptions!$B$20*Assumptions!$D$20*(1+Assumptions!$B$3)^3 -> 290304000 | AX11: =Assumptions!$B$20*Assumptions!$D$20*(1+Assumptions!$B$3)^4 -> 348364800 | AY11: =Assumptions!$B$20*Assumptions!$D$20*(1+Assumptions!$B$3)^4 -> 348364800 | AZ11: =Assumptions!$B$20*Assumptions!$D$20*(1+Assumptions!$B$3)^4 -> 348364800 | BA11: =Assumptions!$B$20*Assumptions!$D$20*(1+Assumptions!$B$3)^4 -> 348364800 | BB11: =Assumptions!$B$20*Assumptions!$D$20*(1+Assumptions!$B$3)^4 -> 348364800 | BC11: =Assumptions!$B$20*Assumptions!$D$20*(1+Assumptions!$B$3)^4 -> 348364800 | BD11: =Assumptions!$B$20*Assumptions!$D$20*(1+Assumptions!$B$3)^4 -> 348364800 | BE11: =Assumptions!$B$20*Assumptions!$D$20*(1+Assumptions!$B$3)^4 -> 348364800 | ... BI11: =Assumptions!$B$20*Assumptions!$D$20*(1+Assumptions!$B$3)^4 -> 348364800
A12: Support | B12: =Assumptions!$B$21*Assumptions!$C$21 -> 30000000 | C12: =Assumptions!$B$21*Assumptions!$C$21 -> 30000000 | D12: =Assumptions!$B$21*Assumptions!$C$21 -> 30000000 | E12: =Assumptions!$B$21*Assumptions!$C$21 -> 30000000 | F12: =Assumptions!$B$21*Assumptions!$C$21 -> 30000000 | G12: =Assumptions!$B$21*Assumptions!$C$21 -> 30000000 | H12: =Assumptions!$B$21*Assumptions!$C$21 -> 30000000 | I12: =Assumptions!$B$21*Assumptions!$C$21 -> 30000000 | ... M12: =Assumptions!$B$21*Assumptions!$C$21 -> 30000000 | N12: =Assumptions!$B$21*Assumptions!$D$21*(1+Assumptions!$B$3) -> 36000000 | O12: =Assumptions!$B$21*Assumptions!$D$21*(1+Assumptions!$B$3) -> 36000000 | P12: =Assumptions!$B$21*Assumptions!$D$21*(1+Assumptions!$B$3) -> 36000000 | Q12: =Assumptions!$B$21*Assumptions!$D$21*(1+Assumptions!$B$3) -> 36000000 | R12: =Assumptions!$B$21*Assumptions!$D$21*(1+Assumptions!$B$3) -> 36000000 | S12: =Assumptions!$B$21*Assumptions!$D$21*(1+Assumptions!$B$3) -> 36000000 | T12: =Assumptions!$B$21*Assumptions!$D$21*(1+Assumptions!$B$3) -> 36000000 | U12: =Assumptions!$B$21*Assumptions!$D$21*(1+Assumptions!$B$3) -> 36000000 | ... Y12: =Assumptions!$B$21*Assumptions!$D$21*(1+Assumptions!$B$3) -> 36000000 | Z12: =Assumptions!$B$21*Assumptions!$D$21*(1+Assumptions!$B$3)^2 -> 43200000 | AA12: =Assumptions!$B$21*Assumptions!$D$21*(1+Assumptions!$B$3)^2 -> 43200000 | AB12: =Assumptions!$B$21*Assumptions!$D$21*(1+Assumptions!$B$3)^2 -> 43200000 | AC12: =Assumptions!$B$21*Assumptions!$D$21*(1+Assumptions!$B$3)^2 -> 43200000 | AD12: =Assumptions!$B$21*Assumptions!$D$21*(1+Assumptions!$B$3)^2 -> 43200000 | AE12: =Assumptions!$B$21*Assumptions!$D$21*(1+Assumptions!$B$3)^2 -> 43200000 | AF12: =Assumptions!$B$21*Assumptions!$D$21*(1+Assumptions!$B$3)^2 -> 43200000 | AG12: =Assumptions!$B$21*Assumptions!$D$21*(1+Assumptions!$B$3)^2 -> 43200000 | ... AK12: =Assumptions!$B$21*Assumptions!$D$21*(1+Assumptions!$B$3)^2 -> 43200000 | AL12: =Assumptions!$B$21*Assumptions!$D$21*(1+Assumptions!$B$3)^3 -> 51840000 | AM12: =Assumptions!$B$21*Assumptions!$D$21*(1+Assumptions!$B$3)^3 -> 51840000 | AN12: =Assumptions!$B$21*Assumptions!$D$21*(1+Assumptions!$B$3)^3 -> 51840000 | AO12: =Assumptions!$B$21*Assumptions!$D$21*(1+Assumptions!$B$3)^3 -> 51840000 | AP12: =Assumptions!$B$21*Assumptions!$D$21*(1+Assumptions!$B$3)^3 -> 51840000 | AQ12: =Assumptions!$B$21*Assumptions!$D$21*(1+Assumptions!$B$3)^3 -> 51840000 | AR12: =Assumptions!$B$21*Assumptions!$D$21*(1+Assumptions!$B$3)^3 -> 51840000 | AS12: =Assumptions!$B$21*Assumptions!$D$21*(1+Assumptions!$B$3)^3 -> 51840000 | ... AW12: =Assumptions!$B$21*Assumptions!$D$21*(1+Assumptions!$B$3)^3 -> 51840000 | AX12: =Assumptions!$B$21*Assumptions!$D$21*(1+Assumptions!$B$3)^4 -> 62208000 | AY12: =Assumptions!$B$21*Assumptions!$D$21*(1+Assumptions!$B$3)^4 -> 62208000 | AZ12: =Assumptions!$B$21*Assumptions!$D$21*(1+Assumptions!$B$3)^4 -> 62208000 | BA12: =Assumptions!$B$21*Assumptions!$D$21*(1+Assumptions!$B$3)^4 -> 62208000 | BB12: =Assumptions!$B$21*Assumptions!$D$21*(1+Assumptions!$B$3)^4 -> 62208000 | BC12: =Assumptions!$B$21*Assumptions!$D$21*(1+Assumptions!$B$3)^4 -> 62208000 | BD12: =Assumptions!$B$21*Assumptions!$D$21*(1+Assumptions!$B$3)^4 -> 62208000 | BE12: =Assumptions!$B$21*Assumptions!$D$21*(1+Assumptions!$B$3)^4 -> 62208000 | ... BI12: =Assumptions!$B$21*Assumptions!$D$21*(1+Assumptions!$B$3)^4 -> 62208000
A13: Overhead | B13: =SUM(B9:B12)*Assumptions!$B$22 -> 69160000 | C13: =SUM(C9:C12)*Assumptions!$B$22 -> 69160000 | D13: =SUM(D9:D12)*Assumptions!$B$22 -> 69160000 | E13: =SUM(E9:E12)*Assumptions!$B$22 -> 69160000 | F13: =SUM(F9:F12)*Assumptions!$B$22 -> 69160000 | G13: =SUM(G9:G12)*Assumptions!$B$22 -> 69160000 | H13: =SUM(H9:H12)*Assumptions!$B$22 -> 69160000 | I13: =SUM(I9:I12)*Assumptions!$B$22 -> 69160000 | ... BI13: =SUM(BI9:BI12)*Assumptions!$B$22 -> 351433728
A14: Total Payroll | B14: =-SUM(B9:B13) -> -251160000 | C14: =-SUM(C9:C13) -> -251160000 | D14: =-SUM(D9:D13) -> -251160000 | E14: =-SUM(E9:E13) -> -251160000 | F14: =-SUM(F9:F13) -> -251160000 | G14: =-SUM(G9:G13) -> -251160000 | H14: =-SUM(H9:H13) -> -251160000 | I14: =-SUM(I9:I13) -> -251160000 | ... BI14: =-SUM(BI9:BI13) -> -1276259328
A16: Marketing
A17: Cost per Ad | B17: =-B3*Assumptions!$B$12 -> -2166052.9 | C17: =-C3*Assumptions!$B$12 -> -2345892.6 | D17: =-D3*Assumptions!$B$12 -> -2540663.7 | E17: =-E3*Assumptions!$B$12 -> -2751606 | F17: =-F3*Assumptions!$B$12 -> -2980062.1 | G17: =-G3*Assumptions!$B$12 -> -3227486.1 | H17: =-H3*Assumptions!$B$12 -> -3495452.8 | I17: =-I3*Assumptions!$B$12 -> -3785667.9 | ... M17: =-M3*Assumptions!$B$12 -> -5208333.3 | N17: =-N3*Assumptions!$C$12 -> -8815530.2 | O17: =-O3*Assumptions!$C$12 -> -10290349 | P17: =-P3*Assumptions!$C$12 -> -12011902 | Q17: =-Q3*Assumptions!$C$12 -> -14021466 | R17: =-R3*Assumptions!$C$12 -> -16367227 | S17: =-S3*Assumptions!$C$12 -> -19105428 | T17: =-T3*Assumptions!$C$12 -> -22301723 | U17: =-U3*Assumptions!$C$12 -> -26032753 | ... Y17: =-Y3*Assumptions!$C$12 -> -48333333 | Z17: =-Z3*Assumptions!$D$12 -> -71749358 | AA17: =-AA3*Assumptions!$D$12 -> -78896097 | AB17: =-AB3*Assumptions!$D$12 -> -86754702 | AC17: =-AC3*Assumptions!$D$12 -> -95396079 | AD17: =-AD3*Assumptions!$D$12 -> -1.048982e+08 | AE17: =-AE3*Assumptions!$D$12 -> -1.1534679e+08 | AF17: =-AF3*Assumptions!$D$12 -> -1.2683614e+08 | AG17: =-AG3*Assumptions!$D$12 -> -1.3946991e+08 | ... AK17: =-AK3*Assumptions!$D$12 -> -203906250 | AL17: =-AL3*Assumptions!$E$12 -> -2.6614378e+08 | AM17: =-AM3*Assumptions!$E$12 -> -2.7790227e+08 | AN17: =-AN3*Assumptions!$E$12 -> -2.9018026e+08 | AO17: =-AO3*Assumptions!$E$12 -> -3.0300071e+08 | AP17: =-AP3*Assumptions!$E$12 -> -3.1638757e+08 | AQ17: =-AQ3*Assumptions!$E$12 -> -3.3036588e+08 | AR17: =-AR3*Assumptions!$E$12 -> -3.4496177e+08 | AS17: =-AS3*Assumptions!$E$12 -> -3.6020251e+08 | ... AW17: =-AW3*Assumptions!$E$12 -> -428203125 | AX17: =-AX3*Assumptions!$F$12 -> -6.2998164e+08 | AY17: =-AY3*Assumptions!$F$12 -> -6.3920175e+08 | AZ17: =-AZ3*Assumptions!$F$12 -> -6.4855679e+08 | BA17: =-BA3*Assumptions!$F$12 -> -6.5804876e+08 | BB17: =-BB3*Assumptions!$F$12 -> -6.6767964e+08 | BC17: =-BC3*Assumptions!$F$12 -> -6.7745147e+08 | BD17: =-BD3*Assumptions!$F$12 -> -6.8736632e+08 | BE17: =-BE3*Assumptions!$F$12 -> -6.9742628e+08 | ... BI17: =-BI3*Assumptions!$F$12 -> -7.3916016e+08
A18: ATL | B18: =-B6*Assumptions!$B$14 -> -2436809.5 | C18: =-C6*Assumptions!$B$14 -> -2639129.2 | D18: =-D6*Assumptions!$B$14 -> -2858246.7 | E18: =-E6*Assumptions!$B$14 -> -3095556.8 | F18: =-F6*Assumptions!$B$14 -> -3352569.9 | G18: =-G6*Assumptions!$B$14 -> -3630921.9 | H18: =-H6*Assumptions!$B$14 -> -3932384.5 | I18: =-I6*Assumptions!$B$14 -> -4258876.4 | ... BI18: =-BI6*Assumptions!$B$14 -> -5.7220459e+08
A19: Total Marketing | B19: =SUM(B17:B18) -> -4602862.4 | C19: =SUM(C17:C18) -> -4985021.8 | D19: =SUM(D17:D18) -> -5398910.4 | E19: =SUM(E17:E18) -> -5847162.8 | F19: =SUM(F17:F18) -> -6332632 | G19: =SUM(G17:G18) -> -6858408 | H19: =SUM(H17:H18) -> -7427837.3 | I19: =SUM(I17:I18) -> -8044544.3 | ... BI19: =SUM(BI17:BI18) -> -1.3113647e+09
A21: G&A
A22: Rent | B22: =-Assumptions!$C$23*Assumptions!$B$26 -> -9800000 | C22: =-Assumptions!$C$23*Assumptions!$B$26 -> -9800000 | D22: =-Assumptions!$C$23*Assumptions!$B$26 -> -9800000 | E22: =-Assumptions!$C$23*Assumptions!$B$26 -> -9800000 | F22: =-Assumptions!$C$23*Assumptions!$B$26 -> -9800000 | G22: =-Assumptions!$C$23*Assumptions!$B$26 -> -9800000 | H22: =-Assumptions!$C$23*Assumptions!$B$26 -> -9800000 | I22: =-Assumptions!$C$23*Assumptions!$B$26 -> -9800000 | ... M22: =-Assumptions!$C$23*Assumptions!$B$26 -> -9800000 | N22: =-Assumptions!$D$23*Assumptions!$B$26*(1+Assumptions!$B$2) -> -24500000 | O22: =-Assumptions!$D$23*Assumptions!$B$26*(1+Assumptions!$B$2) -> -24500000 | P22: =-Assumptions!$D$23*Assumptions!$B$26*(1+Assumptions!$B$2) -> -24500000 | Q22: =-Assumptions!$D$23*Assumptions!$B$26*(1+Assumptions!$B$2) -> -24500000 | R22: =-Assumptions!$D$23*Assumptions!$B$26*(1+Assumptions!$B$2) -> -24500000 | S22: =-Assumptions!$D$23*Assumptions!$B$26*(1+Assumptions!$B$2) -> -24500000 | T22: =-Assumptions!$D$23*Assumptions!$B$26*(1+Assumptions!$B$2) -> -24500000 | U22: =-Assumptions!$D$23*Assumptions!$B$26*(1+Assumptions!$B$2) -> -24500000 | ... Y22: =-Assumptions!$D$23*Assumptions!$B$26*(1+Assumptions!$B$2) -> -24500000 | Z22: =-Assumptions!$E$23*Assumptions!$B$26*(1+Assumptions!$B$2)^2 -> -38281250 | AA22: =-Assumptions!$E$23*Assumptions!$B$26*(1+Assumptions!$B$2)^2 -> -38281250 | AB22: =-Assumptions!$E$23*Assumptions!$B$26*(1+Assumptions!$B$2)^2 -> -38281250 | AC22: =-Assumptions!$E$23*Assumptions!$B$26*(1+Assumptions!$B$2)^2 -> -38281250 | AD22: =-Assumptions!$E$23*Assumptions!$B$26*(1+Assumptions!$B$2)^2 -> -38281250 | AE22: =-Assumptions!$E$23*Assumptions!$B$26*(1+Assumptions!$B$2)^2 -> -38281250 | AF22: =-Assumptions!$E$23*Assumptions!$B$26*(1+Assumptions!$B$2)^2 -> -38281250 | AG22: =-Assumptions!$E$23*Assumptions!$B$26*(1+Assumptions!$B$2)^2 -> -38281250 | ... AK22: =-Assumptions!$E$23*Assumptions!$B$26*(1+Assumptions!$B$2)^2 -> -38281250 | AL22: =-Assumptions!$F$23*Assumptions!$B$26*(1+Assumptions!$B$2)^3 -> -65625000 | AM22: =-Assumptions!$F$23*Assumptions!$B$26*(1+Assumptions!$B$2)^3 -> -65625000 | AN22: =-Assumptions!$F$23*Assumptions!$B$26*(1+Assumptions!$B$2)^3 -> -65625000 | AO22: =-Assumptions!$F$23*Assumptions!$B$26*(1+Assumptions!$B$2)^3 -> -65625000 | AP22: =-Assumptions!$F$23*Assumptions!$B$26*(1+Assumptions!$B$2)^3 -> -65625000 | AQ22: =-Assumptions!$F$23*Assumptions!$B$26*(1+Assumptions!$B$2)^3 -> -65625000 | AR22: =-Assumptions!$F$23*Assumptions!$B$26*(1+Assumptions!$B$2)^3 -> -65625000 | AS22: =-Assumptions!$F$23*Assumptions!$B$26*(1+Assumptions!$B$2)^3 -> -65625000 | ... AW22: =-Assumptions!$F$23*Assumptions!$B$26*(1+Assumptions!$B$2)^3 -> -65625000 | AX22: =-Assumptions!$G$23*Assumptions!$B$26*(1+Assumptions!$B$2)^4 -> -1.4013672e+08 | AY22: =-Assumptions!$G$23*Assumptions!$B$26*(1+Assumptions!$B$2)^4 -> -1.4013672e+08 | AZ22: =-Assumptions!$G$23*Assumptions!$B$26*(1+Assumptions!$B$2)^4 -> -1.4013672e+08 | BA22: =-Assumptions!$G$23*Assumptions!$B$26*(1+Assumptions!$B$2)^4 -> -1.4013672e+08 | BB22: =-Assumptions!$G$23*Assumptions!$B$26*(1+Assumptions!$B$2)^4 -> -1.4013672e+08 | BC22: =-Assumptions!$G$23*Assumptions!$B$26*(1+Assumptions!$B$2)^4 -> -1.4013672e+08 | BD22: =-Assumptions!$G$23*Assumptions!$B$26*(1+Assumptions!$B$2)^4 -> -1.4013672e+08 | BE22: =-Assumptions!$G$23*Assumptions!$B$26*(1+Assumptions!$B$2)^4 -> -1.4013672e+08 | ... BI22: =-Assumptions!$G$23*Assumptions!$B$26*(1+Assumptions!$B$2)^4 -> -1.4013672e+08
A23: Utilitis | B23: =-Assumptions!$C$23*Assumptions!$B$27 -> -2800000 | C23: =-Assumptions!$C$23*Assumptions!$B$27 -> -2800000 | D23: =-Assumptions!$C$23*Assumptions!$B$27 -> -2800000 | E23: =-Assumptions!$C$23*Assumptions!$B$27 -> -2800000 | F23: =-Assumptions!$C$23*Assumptions!$B$27 -> -2800000 | G23: =-Assumptions!$C$23*Assumptions!$B$27 -> -2800000 | H23: =-Assumptions!$C$23*Assumptions!$B$27 -> -2800000 | I23: =-Assumptions!$C$23*Assumptions!$B$27 -> -2800000 | ... M23: =-Assumptions!$C$23*Assumptions!$B$27 -> -2800000 | N23: =-Assumptions!$D$23*Assumptions!$B$27*(1+Assumptions!$B$2) -> -7000000 | O23: =-Assumptions!$D$23*Assumptions!$B$27*(1+Assumptions!$B$2) -> -7000000 | P23: =-Assumptions!$D$23*Assumptions!$B$27*(1+Assumptions!$B$2) -> -7000000 | Q23: =-Assumptions!$D$23*Assumptions!$B$27*(1+Assumptions!$B$2) -> -7000000 | R23: =-Assumptions!$D$23*Assumptions!$B$27*(1+Assumptions!$B$2) -> -7000000 | S23: =-Assumptions!$D$23*Assumptions!$B$27*(1+Assumptions!$B$2) -> -7000000 | T23: =-Assumptions!$D$23*Assumptions!$B$27*(1+Assumptions!$B$2) -> -7000000 | U23: =-Assumptions!$D$23*Assumptions!$B$27*(1+Assumptions!$B$2) -> -7000000 | ... Y23: =-Assumptions!$D$23*Assumptions!$B$27*(1+Assumptions!$B$2) -> -7000000 | Z23: =-Assumptions!$E$23*Assumptions!$B$27*(1+Assumptions!$B$2)^2 -> -10937500 | AA23: =-Assumptions!$E$23*Assumptions!$B$27*(1+Assumptions!$B$2)^2 -> -10937500 | AB23: =-Assumptions!$E$23*Assumptions!$B$27*(1+Assumptions!$B$2)^2 -> -10937500 | AC23: =-Assumptions!$E$23*Assumptions!$B$27*(1+Assumptions!$B$2)^2 -> -10937500 | AD23: =-Assumptions!$E$23*Assumptions!$B$27*(1+Assumptions!$B$2)^2 -> -10937500 | AE23: =-Assumptions!$E$23*Assumptions!$B$27*(1+Assumptions!$B$2)^2 -> -10937500 | AF23: =-Assumptions!$E$23*Assumptions!$B$27*(1+Assumptions!$B$2)^2 -> -10937500 | AG23: =-Assumptions!$E$23*Assumptions!$B$27*(1+Assumptions!$B$2)^2 -> -10937500 | ... AK23: =-Assumptions!$E$23*Assumptions!$B$27*(1+Assumptions!$B$2)^2 -> -10937500 | AL23: =-Assumptions!$F$23*Assumptions!$B$27*(1+Assumptions!$B$2)^3 -> -18750000 | AM23: =-Assumptions!$F$23*Assumptions!$B$27*(1+Assumptions!$B$2)^3 -> -18750000 | AN23: =-Assumptions!$F$23*Assumptions!$B$27*(1+Assumptions!$B$2)^3 -> -18750000 | AO23: =-Assumptions!$F$23*Assumptions!$B$27*(1+Assumptions!$B$2)^3 -> -18750000 | AP23: =-Assumptions!$F$23*Assumptions!$B$27*(1+Assumptions!$B$2)^3 -> -18750000 | AQ23: =-Assumptions!$F$23*Assumptions!$B$27*(1+Assumptions!$B$2)^3 -> -18750000 | AR23: =-Assumptions!$F$23*Assumptions!$B$27*(1+Assumptions!$B$2)^3 -> -18750000 | AS23: =-Assumptions!$F$23*Assumptions!$B$27*(1+Assumptions!$B$2)^3 -> -18750000 | ... AW23: =-Assumptions!$F$23*Assumptions!$B$27*(1+Assumptions!$B$2)^3 -> -18750000 | AX23: =-Assumptions!$G$23*Assumptions!$B$27*(1+Assumptions!$B$2)^4 -> -40039062 | AY23: =-Assumptions!$G$23*Assumptions!$B$27*(1+Assumptions!$B$2)^4 -> -40039062 | AZ23: =-Assumptions!$G$23*Assumptions!$B$27*(1+Assumptions!$B$2)^4 -> -40039062 | BA23: =-Assumptions!$G$23*Assumptions!$B$27*(1+Assumptions!$B$2)^4 -> -40039062 | BB23: =-Assumptions!$G$23*Assumptions!$B$27*(1+Assumptions!$B$2)^4 -> -40039062 | BC23: =-Assumptions!$G$23*Assumptions!$B$27*(1+Assumptions!$B$2)^4 -> -40039062 | BD23: =-Assumptions!$G$23*Assumptions!$B$27*(1+Assumptions!$B$2)^4 -> -40039062 | BE23: =-Assumptions!$G$23*Assumptions!$B$27*(1+Assumptions!$B$2)^4 -> -40039062 | ... BI23: =-Assumptions!$G$23*Assumptions!$B$27*(1+Assumptions!$B$2)^4 -> -40039062
A24: Total G&A | B24: =SUM(B22:B23) -> -12600000 | C24: =SUM(C22:C23) -> -12600000 | D24: =SUM(D22:D23) -> -12600000 | E24: =SUM(E22:E23) -> -12600000 | F24: =SUM(F22:F23) -> -12600000 | G24: =SUM(G22:G23) -> -12600000 | H24: =SUM(H22:H23) -> -12600000 | I24: =SUM(I22:I23) -> -12600000 | ... BI24: =SUM(BI22:BI23) -> -1.8017578e+08
A26: Asset | B26: =Assumptions!$B$28*Assumptions!$C$23 -> 11666667 | C26: =Assumptions!$B$28*Assumptions!$C$23 -> 11666667 | D26: =Assumptions!$B$28*Assumptions!$C$23 -> 11666667 | E26: =Assumptions!$B$28*Assumptions!$C$23 -> 11666667 | F26: =Assumptions!$B$28*Assumptions!$C$23 -> 11666667 | G26: =Assumptions!$B$28*Assumptions!$C$23 -> 11666667 | H26: =Assumptions!$B$28*Assumptions!$C$23 -> 11666667 | I26: =Assumptions!$B$28*Assumptions!$C$23 -> 11666667 | ... M26: =Assumptions!$B$28*Assumptions!$C$23 -> 11666667 | N26: =Assumptions!$B$28*(Assumptions!$D$23-Assumptions!$C$23)*(1+Assumptions!$B$2) -> 14583333 | O26: =Assumptions!$B$28*(Assumptions!$D$23-Assumptions!$C$23)*(1+Assumptions!$B$2) -> 14583333 | P26: =Assumptions!$B$28*(Assumptions!$D$23-Assumptions!$C$23)*(1+Assumptions!$B$2) -> 14583333 | Q26: =Assumptions!$B$28*(Assumptions!$D$23-Assumptions!$C$23)*(1+Assumptions!$B$2) -> 14583333 | R26: =Assumptions!$B$28*(Assumptions!$D$23-Assumptions!$C$23)*(1+Assumptions!$B$2) -> 14583333 | S26: =Assumptions!$B$28*(Assumptions!$D$23-Assumptions!$C$23)*(1+Assumptions!$B$2) -> 14583333 | T26: =Assumptions!$B$28*(Assumptions!$D$23-Assumptions!$C$23)*(1+Assumptions!$B$2) -> 14583333 | U26: =Assumptions!$B$28*(Assumptions!$D$23-Assumptions!$C$23)*(1+Assumptions!$B$2) -> 14583333 | ... Y26: =Assumptions!$B$28*(Assumptions!$D$23-Assumptions!$C$23)*(1+Assumptions!$B$2) -> 14583333 | Z26: =Assumptions!$B$28*(Assumptions!$E$23-Assumptions!$D$23)*(1+Assumptions!$B$2)^2 -> 9114583.3 | AA26: =Assumptions!$B$28*(Assumptions!$E$23-Assumptions!$D$23)*(1+Assumptions!$B$2)^2 -> 9114583.3 | AB26: =Assumptions!$B$28*(Assumptions!$E$23-Assumptions!$D$23)*(1+Assumptions!$B$2)^2 -> 9114583.3 | AC26: =Assumptions!$B$28*(Assumptions!$E$23-Assumptions!$D$23)*(1+Assumptions!$B$2)^2 -> 9114583.3 | AD26: =Assumptions!$B$28*(Assumptions!$E$23-Assumptions!$D$23)*(1+Assumptions!$B$2)^2 -> 9114583.3 | AE26: =Assumptions!$B$28*(Assumptions!$E$23-Assumptions!$D$23)*(1+Assumptions!$B$2)^2 -> 9114583.3 | AF26: =Assumptions!$B$28*(Assumptions!$E$23-Assumptions!$D$23)*(1+Assumptions!$B$2)^2 -> 9114583.3 | AG26: =Assumptions!$B$28*(Assumptions!$E$23-Assumptions!$D$23)*(1+Assumptions!$B$2)^2 -> 9114583.3 | ... AK26: =Assumptions!$B$28*(Assumptions!$E$23-Assumptions!$D$23)*(1+Assumptions!$B$2)^2 -> 9114583.3 | AL26: =Assumptions!$B$28*(Assumptions!$F$23-Assumptions!$D$23)*(1+Assumptions!$B$2)^3 -> 32552083 | AM26: =Assumptions!$B$28*(Assumptions!$F$23-Assumptions!$D$23)*(1+Assumptions!$B$2)^3 -> 32552083 | AN26: =Assumptions!$B$28*(Assumptions!$F$23-Assumptions!$D$23)*(1+Assumptions!$B$2)^3 -> 32552083 | AO26: =Assumptions!$B$28*(Assumptions!$F$23-Assumptions!$D$23)*(1+Assumptions!$B$2)^3 -> 32552083 | AP26: =Assumptions!$B$28*(Assumptions!$F$23-Assumptions!$D$23)*(1+Assumptions!$B$2)^3 -> 32552083 | AQ26: =Assumptions!$B$28*(Assumptions!$F$23-Assumptions!$D$23)*(1+Assumptions!$B$2)^3 -> 32552083 | AR26: =Assumptions!$B$28*(Assumptions!$F$23-Assumptions!$D$23)*(1+Assumptions!$B$2)^3 -> 32552083 | AS26: =Assumptions!$B$28*(Assumptions!$F$23-Assumptions!$D$23)*(1+Assumptions!$B$2)^3 -> 32552083 | ... AW26: =Assumptions!$B$28*(Assumptions!$F$23-Assumptions!$D$23)*(1+Assumptions!$B$2)^3 -> 32552083 | AX26: =Assumptions!$B$28*(Assumptions!$G$23-Assumptions!$F$23)*(1+Assumptions!$B$2)^4 -> 69173177 | AY26: =Assumptions!$B$28*(Assumptions!$G$23-Assumptions!$F$23)*(1+Assumptions!$B$2)^4 -> 69173177 | AZ26: =Assumptions!$B$28*(Assumptions!$G$23-Assumptions!$F$23)*(1+Assumptions!$B$2)^4 -> 69173177 | BA26: =Assumptions!$B$28*(Assumptions!$G$23-Assumptions!$F$23)*(1+Assumptions!$B$2)^4 -> 69173177 | BB26: =Assumptions!$B$28*(Assumptions!$G$23-Assumptions!$F$23)*(1+Assumptions!$B$2)^4 -> 69173177 | BC26: =Assumptions!$B$28*(Assumptions!$G$23-Assumptions!$F$23)*(1+Assumptions!$B$2)^4 -> 69173177 | BD26: =Assumptions!$B$28*(Assumptions!$G$23-Assumptions!$F$23)*(1+Assumptions!$B$2)^4 -> 69173177 | BE26: =Assumptions!$B$28*(Assumptions!$G$23-Assumptions!$F$23)*(1+Assumptions!$B$2)^4 -> 69173177 | ... BI26: =Assumptions!$B$28*(Assumptions!$G$23-Assumptions!$F$23)*(1+Assumptions!$B$2)^4 -> 69173177
A28: Depraction | B28: =-B26*Assumptions!$F$3 -> -2333333.3 | C28: =-C26*Assumptions!$F$3 -> -2333333.3 | D28: =-D26*Assumptions!$F$3 -> -2333333.3 | E28: =-E26*Assumptions!$F$3 -> -2333333.3 | F28: =-F26*Assumptions!$F$3 -> -2333333.3 | G28: =-G26*Assumptions!$F$3 -> -2333333.3 | H28: =-H26*Assumptions!$F$3 -> -2333333.3 | I28: =-I26*Assumptions!$F$3 -> -2333333.3 | ... BI28: =-BI26*Assumptions!$F$3 -> -13834635
A29: EBIT | B29: =B6+SUM(B14,B19,B24,B28) -> -2.463281e+08 | C29: =C6+SUM(C14,C19,C24,C28) -> -2.4468706e+08 | D29: =D6+SUM(D14,D19,D24,D28) -> -2.4290978e+08 | E29: =E6+SUM(E14,E19,E24,E28) -> -2.4098493e+08 | F29: =F6+SUM(F14,F19,F24,F28) -> -2.3890027e+08 | G29: =G6+SUM(G14,G19,G24,G28) -> -2.3664252e+08 | H29: =H6+SUM(H14,H19,H24,H28) -> -2.3419733e+08 | I29: =I6+SUM(I14,I19,I24,I28) -> -2.3154911e+08 | ... BI29: =BI6+SUM(BI14,BI19,BI24,BI28) -> 2.9404114e+09
A30: TAX | B30: =IF(B29>=0,-B29*Assumptions!$F$2,0) -> 0 | C30: =IF(C29>=0,-C29*Assumptions!$F$2,0) -> 0 | D30: =IF(D29>=0,-D29*Assumptions!$F$2,0) -> 0 | E30: =IF(E29>=0,-E29*Assumptions!$F$2,0) -> 0 | F30: =IF(F29>=0,-F29*Assumptions!$F$2,0) -> 0 | G30: =IF(G29>=0,-G29*Assumptions!$F$2,0) -> 0 | H30: =IF(H29>=0,-H29*Assumptions!$F$2,0) -> 0 | I30: =IF(I29>=0,-I29*Assumptions!$F$2,0) -> 0 | ... BI30: =IF(BI29>=0,-BI29*Assumptions!$F$2,0) -> -7.3510285e+08
A31: Net Income | B31: =B29+B30 -> -2.463281e+08 | C31: =C29+C30 -> -2.4468706e+08 | D31: =D29+D30 -> -2.4290978e+08 | E31: =E29+E30 -> -2.4098493e+08 | F31: =F29+F30 -> -2.3890027e+08 | G31: =G29+G30 -> -2.3664252e+08 | H31: =H29+H30 -> -2.3419733e+08 | I31: =I29+I30 -> -2.3154911e+08 | ... BI31: =BI29+BI30 -> 2.2053086e+09
A33: FCF | B33: =B31-B28-B26 -> -2.5566143e+08 | C33: =C31-C28-C26 -> -2.540204e+08 | D33: =D31-D28-D26 -> -2.5224311e+08 | E33: =E31-E28-E26 -> -2.5031826e+08 | F33: =F31-F28-F26 -> -2.482336e+08 | G33: =G31-G28-G26 -> -2.4597586e+08 | H33: =H31-H28-H26 -> -2.4353066e+08 | I33: =I31-I28-I26 -> -2.4088245e+08 | ... BI33: =BI31-BI28-BI26 -> 2.14997e+09
A34: Cumulative FCF | B34: =B33 -> -2.5566143e+08 | C34: =B34+C33 -> -5.0968183e+08 | D34: =C34+D33 -> -7.6192494e+08 | E34: =D34+E33 -> -1.0122432e+09 | F34: =E34+F33 -> -1.2604768e+09 | G34: =F34+G33 -> -1.5064527e+09 | H34: =G34+H33 -> -1.7499833e+09 | I34: =H34+I33 -> -1.9908658e+09 | J34: =I34+J33 -> -2.2288801e+09 | ... BI34: =BH34+BI33 -> 2.4103605e+10
A35: Cash need | B35: =MIN($B34:$XFD34) -> -1.0864674e+10

Sheet Summary
B1: Year 0 | C1: Year 1 | D1: Year 2 | E1: Year 3 | F1: Year 4 | G1: Year 5
A2: Acqusitions | B2: =B4/G4 -> 0.0096 | C2: =2.5%-B2 -> 0.0154 | D2: 0.135 | E2: 0.34 | F2: 0.34 | G2: 0.16
A3: Rogers Model | B3: =B2 -> 0.0096 | C3: =C2+B3 -> 0.025 | D3: =D2+C3 -> 0.16 | E3: =E2+D3 -> 0.5 | F3: =F2+E3 -> 0.84 | G3: =G2+F3 -> 1
A4: Last Month Ads | B4: 100 | C4: =C3*$G$4 -> 260.41667 | D4: =D3*$G$4 -> 1666.6667 | E4: =E3*$G$4 -> 5208.3333 | F4: =F3*$G$4 -> 8750 | G4: ='Market Size'!B8 -> 10416.667
A5: Revenue | B5: =B4*Assumptions!B7 -> 25000000 | C5: =SUM('P&L'!B6:M6) -> 4.7081965e+08 | D5: =SUM('P&L'!N6:Y6) -> 2.7596024e+09 | E5: =SUM('P&L'!Z6:AK6) -> 1.3745413e+10 | F5: =SUM('P&L'!AL6:AW6) -> 3.6784155e+10 | G5: =SUM('P&L'!AX6:BI6) -> 6.3470714e+10
A6: Total Payroll | C6: =SUM('P&L'!B14:M14) -> -3013920000 | D6: =SUM('P&L'!N14:Y14) -> -8068032000 | E6: =SUM('P&L'!Z14:AK14) -> -10158566400 | F6: =SUM('P&L'!AL14:AW14) -> -12762593280 | G6: =SUM('P&L'!AX14:BI14) -> -15315111936
A7: ='P&L'!A19 -> Total Marketing | C7: =SUM('P&L'!B19:M19) -> -88932601 | D7: =SUM('P&L'!N19:Y19) -> -5.6050592e+08 | E7: =SUM('P&L'!Z19:AK19) -> -2.9052306e+09 | F7: =SUM('P&L'!AL19:AW19) -> -7.7746989e+09 | G7: =SUM('P&L'!AX19:BI19) -> -1.4546066e+10
A8: ='P&L'!A24 -> Total G&A | C8: =SUM('P&L'!B24:M24) -> -151200000 | D8: =SUM('P&L'!N23:Y23) -> -84000000 | E8: =SUM('P&L'!Z24:AK24) -> -590625000 | F8: =SUM('P&L'!AL24:AW24) -> -1012500000 | G8: =SUM('P&L'!AX24:BI24) -> -2162109375
A9: ='P&L'!A26 -> Asset | C9: =SUM('P&L'!B26:M26) -> 1.4e+08 | D9: =SUM('P&L'!N26:Y26) -> 1.75e+08 | E9: =SUM('P&L'!Z26:AK26) -> 1.09375e+08 | F9: =SUM('P&L'!AL26:AW26) -> 390625000 | G9: =SUM('P&L'!AX26:BI26) -> 8.3007813e+08
A10: ='P&L'!A28 -> Depraction | C10: =SUM('P&L'!B28:M28) -> -28000000 | D10: =SUM('P&L'!N28:Y28) -> -35000000 | E10: =SUM('P&L'!Z28:AK28) -> -21875000 | F10: =SUM('P&L'!AL28:AW28) -> -78125000 | G10: =SUM('P&L'!AX28:BI28) -> -166015625
A11: ='P&L'!A29 -> EBIT | C11: =SUM('P&L'!B29:M29) -> -2.8112329e+09 | D11: =SUM('P&L'!N29:Y29) -> -6.2819355e+09 | E11: =SUM('P&L'!Z29:AK29) -> 69116380 | F11: =SUM('P&L'!AL29:AW29) -> 1.5156237e+10 | G11: =SUM('P&L'!AX29:BI29) -> 3.1281411e+10
A12: ='P&L'!A30 -> TAX | C12: =SUM('P&L'!B30:M30) -> 0 | D12: =SUM('P&L'!N30:Y30) -> 0 | E12: =SUM('P&L'!Z30:AK30) -> -3.8451721e+08 | F12: =SUM('P&L'!AL30:AW30) -> -3.7890594e+09 | G12: =SUM('P&L'!AX30:BI30) -> -7.8203529e+09
A13: ='P&L'!A31 -> Net Income | C13: =SUM('P&L'!B31:M31) -> -2.8112329e+09 | D13: =SUM('P&L'!N31:Y31) -> -6.2819355e+09 | E13: =SUM('P&L'!Z31:AK31) -> -3.1540083e+08 | F13: =SUM('P&L'!AL31:AW31) -> 1.1367178e+10 | G13: =SUM('P&L'!AX31:BI31) -> 2.3461059e+10
A14: ='P&L'!A33 -> FCF | C14: =SUM('P&L'!B33:M33) -> -2.9232329e+09 | D14: =SUM('P&L'!N33:Y33) -> -6.4219355e+09 | E14: =SUM('P&L'!Z33:AK33) -> -4.0290083e+08 | F14: =SUM('P&L'!AL33:AW33) -> 1.1054678e+10 | G14: =SUM('P&L'!AX33:BI33) -> 2.2796996e+10

Sheet Valuation
A1: Assumptions | M1: First Chicago | N1: Success | O1: Survive | P1: Failure
A2: DR | B2: 0.8 | M2: Rate Of Success | N2: =(1-P2)*0.3 -> 0.225 | O2: =(1-P2)*0.7 -> 0.525 | P2: 0.25
A3: DRtv | B3: 0.45 | M3: Revenue At year 5 | N3: =Summary!G5*1.5 -> 9.5206072e+10 | O3: 46000000000 | P3: 0
A4: g | B4: 0.25 | M4: Multiple Revenue | N4: =B16 -> 8 | O4: =N4 -> 8 | P4: =O4 -> 8
A5: DCF Valuation | M5: Valuation Year 5 | N5: =N3*N4*(1-$B$18) -> 5.9408589e+11 | O5: =O3*O4*(1-$B$18) -> 287040000000 | P5: =P3*P4*(1-$B$18) -> 0
A6: YEAR | B6: 1 | C6: 2 | D6: 3 | E6: 4 | F6: 5 | M6: PV of Valuation | N6: =N5/(1+$B$2)^5 -> 3.1440302e+10 | O6: =O5/(1+$B$2)^5 -> 1.5190774e+10 | P6: =P5/(1+$B$2)^5 -> 0
A7: FCF | B7: =Summary!C14 -> -2.9232329e+09 | C7: =Summary!D14 -> -6.4219355e+09 | D7: =Summary!E14 -> -4.0290083e+08 | E7: =Summary!F14 -> 1.1054678e+10 | F7: =Summary!G14 -> 2.2796996e+10 | M7: Sum Product | N7: =SUMPRODUCT(N2:P2,N6:P6) -> 1.5049224e+10
A8: Discunted FCF | B8: =B7/(1+$B$2)^B6 -> -1.6240183e+09 | C8: =C7/(1+$B$2)^C6 -> -1.9820789e+09 | D8: =D7/(1+$B$2)^D6 -> -69084504 | E8: =E7/(1+$B$2)^E6 -> 1.0530672e+09 | F8: =F7/(1+$B$2)^F6 -> 1.206466e+09 | M8: Pre-Money Valution | O8: =N7+B14 -> 8.3943139e+09 | P8: =(((1+0.8)*(1+P2))-1) -> 1.25
A9: PV | B9: =SUM(B8:F8) -> -1.4156484e+09 | G9: DR/DRtv
A10: TV1 | B10: =(F7*(1+B4)/((B3-B4))) -> 1.4248123e+11 | C10: DR/DRtv | D10: =B13 -> 6.1247643e+09 | E10: 0.74 | F10: 0.76 | G10: 0.78 | H10: 0.8 | I10: 0.82 | J10: 0.84 | O10: Failure Rate
A11: TV2 | B11: =Summary!G5*Valuation!B16*(1-B18) -> 3.9605726e+11 | D11: 0.38 | E11: 1.2501223e+10 | F11: 1.1674213e+10 | G11: 1.0903577e+10 | H11: 1.0184987e+10 | I11: 9.5144868e+09 | J11: 8.8884594e+09 | M11: =O8 -> 8.3943139e+09 | N11: 0.2 | O11: 0.25 | P11: 0.3 | Q11: 0.35 | R11: 0.4 | S11: 0.45 | T11: 0.5
A12: PV of TV1 | B12: =B10/(1+B2)^5 -> 7.5404127e+09 | D12: 0.4 | E12: 1.0668754e+10 | F12: 9.9435211e+09 | G12: 9.2679544e+09 | H12: 8.6382352e+09 | I12: 8.0508744e+09 | J12: 7.5026806e+09 | M12: 8 | N12: 9.3975955e+09 | O12: 8.3943139e+09 | P12: 7.3910323e+09 | Q12: 6.3877507e+09 | R12: 5.3844691e+09 | S12: 4.3811874e+09 | T12: 3.3779058e+09
A13: Pre-Money Valuation | B13: =B12+B9 -> 6.1247643e+09 | D13: 0.42 | E13: 9.2674533e+09 | F13: 8.620051e+09 | G13: 8.0171844e+09 | H13: 7.4554253e+09 | I13: 6.9316413e+09 | J13: 6.4429674e+09
A14: Cashneed | B14: =((B7)/(1+Assumptions!$B$2))+(C7/((1+Assumptions!$B$2))^2)+(D7/(1+Assumptions!$B$2)^3) -> -6.6549103e+09 | D14: 0.44 | E14: 8.1611636e+09 | F14: 7.5752063e+09 | G14: 7.0297345e+09 | H14: 6.5216281e+09 | I14: 6.0480363e+09 | J14: 5.6063518e+09
A15: Multiple | D15: 0.46 | E15: 7.2655958e+09 | F15: 6.7293796e+09 | G15: 6.2303702e+09 | H15: 5.765697e+09 | I15: 5.332737e+09 | J15: 4.9290915e+09 | M15: VC- Method
A16: EV/R | B16: 8 | D16: 0.48 | E16: 6.5257789e+09 | F16: 6.0306531e+09 | G16: 5.5700258e+09 | H16: 5.1412322e+09 | I16: 4.7418376e+09 | J16: 4.3696156e+09 | M16: Exit Year | N16: 4
A17: EV/E | B17: 13 | D17: 0.5 | E17: 5.9043326e+09 | F17: 5.4437229e+09 | G17: 5.0153365e+09 | H17: 4.6166817e+09 | I17: 4.2454821e+09 | J17: 3.8996558e+09 | M17: ROE | N17: 10
A18: DLOM | B18: 0.22 | M18: Discount Rate VC Annuly | N18: =(N17/1)^(1/N16)-1 -> 0.77827941
A19: Last Year EV/R Valuation | B19: =B16*Summary!G5*(1-Valuation!B18) -> 3.9605726e+11 | G19: DR/g | N19: Min | O19: Max
A20: Last Year EV/E Valuation | B20: =B17*Summary!G13*(1-Valuation!B18) -> 2.3789513e+11 | D20: =B13 -> 6.1247643e+09 | E20: 0.74 | F20: 0.76 | G20: 0.78 | H20: 0.8 | I20: 0.82 | J20: 0.84 | M20: Revenue at year 5 | N20: =Summary!G5*0.9 -> 5.7123643e+10 | O20: =Summary!G5*1.1 -> 6.9817786e+10
A21: PV EV/R Valuation | B21: =B19/(1+$B$2)^5 -> 2.0960201e+10 | D21: 0.22 | E21: 6.339345e+09 | F21: 5.8545741e+09 | G21: 5.403619e+09 | H21: 4.983867e+09 | I21: 4.592931e+09 | J21: 4.2286276e+09 | M21: Multiple EV/R | N21: =B16 -> 8 | O21: =N21 -> 8
A22: PV EV/E Valuation | B22: =B20/(1+$B$2)^5 -> 1.2589922e+10 | D22: 0.23 | E22: 6.7489345e+09 | F22: 6.2414144e+09 | G22: 5.7692097e+09 | H22: 5.3295935e+09 | I22: 4.9200744e+09 | J22: 4.5383738e+09 | M22: Valuation year 5 | N22: =N21*N20*(1-$B$18) -> 3.5645153e+11 | O22: =O21*O20*(1-$B$18) -> 4.3566298e+11
A23: EV/R Pre-Money Valuation | B23: =B21+$B$14 -> 1.4305291e+10 | D23: 0.24 | E23: 7.1975326e+09 | F23: 6.6650967e+09 | G23: 6.1696185e+09 | H23: 5.7082462e+09 | I23: 5.2783743e+09 | J23: 4.8776197e+09 | M23: Pv of Valuation | N23: =N22/(1+$N$18)^5 -> 2.0044743e+10 | O23: =O22/(1+$N$18)^5 -> 2.449913e+10
A24: EV/E Pre-Money Valuation | B24: =B22+$B$14 -> 5.9350115e+09 | D24: 0.25 | E24: 7.6909905e+09 | F24: 7.1311472e+09 | G24: 6.6100682e+09 | H24: 6.1247643e+09 | I24: 5.6725042e+09 | J24: 5.2507901e+09 | M24: Average Pre-Money Valuation | N24: =N23+$B$14 -> 1.3389832e+10 | O24: =O23+$B$14 -> 1.784422e+10
D25: 0.26 | E25: 8.2363913e+09 | F25: 7.6462557e+09 | G25: 7.0968811e+09 | H25: 6.5851263e+09 | I25: 6.1081215e+09 | J25: 5.6632416e+09 | N25: =AVERAGE(N24:O24) -> 1.5617026e+10
D26: 0.27 | E26: 8.8423922e+09 | F26: 8.2185985e+09 | G26: 7.6377842e+09 | H26: 7.0966397e+09 | I26: 6.5921407e+09 | J26: 6.1215211e+09
D27: 0.28 | E27: 9.5196874e+09 | F27: 8.8582756e+09 | G27: 8.242323e+09 | H27: 7.6683311e+09 | I27: 7.1331033e+09 | J27: 6.6337158e+09
G29: DR/EV-R
D30: =B23 -> 1.4305291e+10 | E30: 0.74 | F30: 0.76 | G30: 0.78 | H30: 0.8 | I30: 0.82 | J30: 0.84
D31: 7.5 | E31: 1.6625092e+10 | F31: 1.5332087e+10 | G31: 1.412431e+10 | H31: 1.2995278e+10 | I31: 1.1939068e+10 | J31: 1.0950256e+10
D32: 7.7 | E32: 1.7245892e+10 | F32: 1.5918406e+10 | G32: 1.4678422e+10 | H32: 1.3519284e+10 | I32: 1.2434907e+10 | J32: 1.1419727e+10
D33: 7.9 | E33: 1.7866692e+10 | F33: 1.6504726e+10 | G33: 1.5232535e+10 | H33: 1.4043289e+10 | I33: 1.2930747e+10 | J33: 1.1889198e+10
D34: 8.1 | E34: 1.8487492e+10 | F34: 1.7091046e+10 | G34: 1.5786647e+10 | H34: 1.4567294e+10 | I34: 1.3426586e+10 | J34: 1.235867e+10
D35: 8.3 | E35: 1.9108292e+10 | F35: 1.7677366e+10 | G35: 1.634076e+10 | H35: 1.5091299e+10 | I35: 1.3922425e+10 | J35: 1.2828141e+10
D36: 8.5 | E36: 1.9729092e+10 | F36: 1.8263686e+10 | G36: 1.6894872e+10 | H36: 1.5615304e+10 | I36: 1.4418265e+10 | J36: 1.3297612e+10
G38: DR/ EV-E
D39: =B24 -> 5.9350115e+09 | E39: 0.74 | F39: 0.76 | G39: 0.78 | H39: 0.8 | I39: 0.82 | J39: 0.84
D40: 12.5 | E40: 7.6869662e+09 | F40: 6.8903976e+09 | G40: 6.1463347e+09 | H40: 5.4507838e+09 | I40: 4.8000946e+09 | J40: 4.1909275e+09
D41: 12.7 | E41: 7.9164362e+09 | F41: 7.1071225e+09 | G41: 6.3511546e+09 | H41: 5.6444749e+09 | I41: 4.9833747e+09 | J41: 4.3644609e+09
D42: 12.9 | E42: 8.1459063e+09 | F42: 7.3238474e+09 | G42: 6.5559745e+09 | H42: 5.838166e+09 | I42: 5.1666548e+09 | J42: 4.5379943e+09
...
